[ 2025-08-14 01:18:58,953 ] 97 werkzeug - INFO - [31m[1mWARNING: This is a development server. Do not use it in a production deployment. Use a production WSGI server instead.[0m
 * Running on all addresses (0.0.0.0)
 * Running on http://127.0.0.1:5000
 * Running on http://10.240.154.33:5000
[ 2025-08-14 01:18:58,954 ] 97 werkzeug - INFO - [33mPress CTRL+C to quit[0m
[ 2025-08-14 01:23:21,043 ] 97 werkzeug - INFO - 127.0.0.1 - - [14/Aug/2025 01:23:21] "GET / HTTP/1.1" 200 -
[ 2025-08-14 01:23:21,119 ] 97 werkzeug - INFO - 127.0.0.1 - - [14/Aug/2025 01:23:21] "[33mGET /favicon.ico HTTP/1.1[0m" 404 -
[ 2025-08-14 01:24:36,550 ] 97 werkzeug - INFO - 127.0.0.1 - - [14/Aug/2025 01:24:36] "GET /predictdata HTTP/1.1" 200 -
[ 2025-08-14 01:25:09,569 ] 875 app - ERROR - Exception on /predictdata [POST]
Traceback (most recent call last):
  File "E:\ML_project\src\pipeline\predict_pipeline.py", line 13, in predict
    model_path=os.path.join("artifacts","model.pkl")
               ^^
NameError: name 'os' is not defined. Did you forget to import 'os'?

During handling of the above exception, another exception occurred:

Traceback (most recent call last):
  File "C:\Users\Lenovo\miniconda31\Lib\site-packages\flask\app.py", line 1511, in wsgi_app
    response = self.full_dispatch_request()
  File "C:\Users\Lenovo\miniconda31\Lib\site-packages\flask\app.py", line 919, in full_dispatch_request
    rv = self.handle_user_exception(e)
  File "C:\Users\Lenovo\miniconda31\Lib\site-packages\flask\app.py", line 917, in full_dispatch_request
    rv = self.dispatch_request()
  File "C:\Users\Lenovo\miniconda31\Lib\site-packages\flask\app.py", line 902, in dispatch_request
    return self.ensure_sync(self.view_functions[rule.endpoint])(**view_args)  # type: ignore[no-any-return]
           ~~~~~~~~~~~~~~~~~~~~~~~~~~~~~~~~~~~~~~~~~~~~~~~~~~~~^^^^^^^^^^^^^
  File "E:\ML_project\app.py", line 39, in predict_datapoint
    results=predict_pipeline.predict(pred_df)
  File "E:\ML_project\src\pipeline\predict_pipeline.py", line 24, in predict
    raise CustomException(e,sys)
src.exception.CustomException: Error occured in python script name [E:\ML_project\src\pipeline\predict_pipeline.py] line number [13] error message[name 'os' is not defined]
[ 2025-08-14 01:25:09,628 ] 97 werkzeug - INFO - 127.0.0.1 - - [14/Aug/2025 01:25:09] "[35m[1mPOST /predictdata HTTP/1.1[0m" 500 -
